Workbook
Name ____kl1: {#N/A,#N/A,FALSE,"Aging Summary";#N/A,#N/A,FALSE,"Ratio Analysis";#N/A,#N/A,FALSE,"Test 120 Day Accts";#N/A,#N/A,FALSE,"Tickmarks"}
Name ____kl1: {#N/A,#N/A,FALSE,"Aging Summary";#N/A,#N/A,FALSE,"Ratio Analysis";#N/A,#N/A,FALSE,"Test 120 Day Accts";#N/A,#N/A,FALSE,"Tickmarks"}
Name ___kl1: {#N/A,#N/A,FALSE,"Aging Summary";#N/A,#N/A,FALSE,"Ratio Analysis";#N/A,#N/A,FALSE,"Test 120 Day Accts";#N/A,#N/A,FALSE,"Tickmarks"}
Name ___kl1: {#N/A,#N/A,FALSE,"Aging Summary";#N/A,#N/A,FALSE,"Ratio Analysis";#N/A,#N/A,FALSE,"Test 120 Day Accts";#N/A,#N/A,FALSE,"Tickmarks"}
Name __123Graph_ACurrent: [1]Inventories!$A$4:$A$9
Name __123Graph_BCurrent: [1]Inventories!$B$4:$B$9
Name __123Graph_CCurrent: [1]Inventories!$C$4:$C$9
Name __123Graph_DCurrent: [1]Inventories!$D$4:$D$9
Name __123Graph_ECurrent: [1]Inventories!$E$4:$E$9
Name __123Graph_FCurrent: [1]Inventories!$F$4:$F$9
Name __aje2: 5
Name __CAc02: '[2]Customer accs'!#REF!
Name __CAc03: '[2]Customer accs'!#REF!
Name __FRX02: [2]Forex!#REF!
Name __FRX03: [2]Forex!#REF!
Name __kl1: {#N/A,#N/A,FALSE,"Aging Summary";#N/A,#N/A,FALSE,"Ratio Analysis";#N/A,#N/A,FALSE,"Test 120 Day Accts";#N/A,#N/A,FALSE,"Tickmarks"}
Name __kl1: {#N/A,#N/A,FALSE,"Aging Summary";#N/A,#N/A,FALSE,"Ratio Analysis";#N/A,#N/A,FALSE,"Test 120 Day Accts";#N/A,#N/A,FALSE,"Tickmarks"}
Name __LFB02: '[2]Loans from Banks'!#REF!
Name __LTB02: '[2]Loans to Banks'!#REF!
Name __LTC02: [2]Loans!#REF!
Name __OpE02: [2]OpExp!#REF!
Name __OpE03: [2]OpExp!#REF!
Name __Ref3: [3]Technical!#REF!
Name __SIs02: #REF!
Name __SIs03: #REF!
Name __xlnm._FilterDatabase_1_1: #REF!
Name __xlnm._FilterDatabase_1_1: #REF!
Name __xlnm._FilterDatabase_11: #REF!
Name __xlnm._FilterDatabase_11: #REF!
Name __xlnm._FilterDatabase_12: '[4]822200'!#REF!
Name __xlnm._FilterDatabase_12: '[4]822200'!#REF!
Name __xlnm._FilterDatabase_13: #REF!
Name __xlnm._FilterDatabase_13: #REF!
Name __xlnm._FilterDatabase_14: #REF!
Name __xlnm._FilterDatabase_14: #REF!
Name __xlnm._FilterDatabase_15: #REF!
Name __xlnm._FilterDatabase_15: #REF!
Name __xlnm._FilterDatabase_16: #REF!
Name __xlnm._FilterDatabase_16: #REF!
Name __xlnm._FilterDatabase_17: #REF!
Name __xlnm._FilterDatabase_17: #REF!
Name __xlnm._FilterDatabase_18: #REF!
Name __xlnm._FilterDatabase_18: #REF!
Name __xlnm._FilterDatabase_2: #REF!
Name __xlnm._FilterDatabase_2: #REF!
Name __xlnm._FilterDatabase_29: #REF!
Name __xlnm._FilterDatabase_29: #REF!
Name __xlnm._FilterDatabase_3: #REF!
Name __xlnm._FilterDatabase_3: #REF!
Name __xlnm._FilterDatabase_30: #REF!
Name __xlnm._FilterDatabase_30: #REF!
Name __xlnm._FilterDatabase_32: #REF!
Name __xlnm._FilterDatabase_32: #REF!
Name __xlnm._FilterDatabase_4: #REF!
Name __xlnm._FilterDatabase_4: #REF!
Name __xlnm._FilterDatabase_5: #REF!
Name __xlnm._FilterDatabase_5: #REF!
Name __xlnm._FilterDatabase_6: #REF!
Name __xlnm._FilterDatabase_6: #REF!
Name __xlnm._FilterDatabase_7: #REF!

Sheet Pivot
A3: Група | B3: Підгрупа
A4: Розвиток цифрових навичок населення | B4: Розвиток талантів в галузі ІКТ
B5: Розвиток цифрової грамотності населення
A6: Цифрова економіка в ТГ | B6: Привабливість для інвестицій в галузь ІТ
B7: Розвиток підприємств ІТ-сектору в ТГ
B8: Цифрові технології для бізнесу
A9: Цифрова інфраструктура в ТГ | B9: Кібербезпека
B10: Створення безпечного середовища
B11: Якість та доступність цифрової інфраструктури
A12: Цифрова трансформація ОМС | B12: Автоматизація управлінської діяльності та систем управління ресурсами
B13: Інституційна спроможність
B14: Публічності та прозорості ОМС/Інструменти е-Демократії
A15: Цифровізація публічних послуг | B15: Соціально вразливі групи населення
B16: Цифровий розвиток послуг галузей освіти і охорони здоров'я
B17: Цифровий розвиток публічних послуг для населення
B18: Цифровізація транспортної інфраструктури
A19: Загальний підсумок

Sheet Титульний аркуш
O3: Додаток 1
A12: ПАСПОРТ ІНДИКАТОРІВ Індексу цифрової трансформації ТГ
B36: Версія: | G36: 1.0
B37: Дата створення:
B38: Дата внесення змін:
K48: Київ 2022

Sheet Журнал змін
O13: Перелік внесених змін
O15: № | P15: Версія | Q15: Коментар
O16: 1 | P16: 1.00

Sheet Перелік Iндикаторiв
B3: Група | C3: Підгрупа | D3: # Індикатора | E3: Назва індикатора | G3: Одиниці вимірювання індикатора (Ов) | H3: Структура індексу | I3: вид індикатора | J3: Характер даних | K3: Цільове значення індикатора | L3: вага індикатора Розширений | M3: вага індикатора Базовий
B4: Цифрова економіка в ТГ | C4: Розвиток підприємств ІТ-сектору в ТГ | D4: A.1.1 | E4: % суб'єктів підприємницької діяльності (СПД) із КВЕДами ІТ-галузі у загальній кількості тих, які були відкриті та/або переміщені з інших ТГ протягом звітного періоду | G4: % | H4: Базовий | I4: Обов'язковий для вимірювання | J4: Кількісні дані | K4: 0.05 | L4: 0.15384615 | M4: 0.15384615
B5: Цифрова економіка в ТГ | C5: Розвиток підприємств ІТ-сектору в ТГ | D5: A.1.2 | E5: % у надходженнях від сплати ПДФО в бюджет ТГ, що надійшли від підприємств, що працюють в ІТ-галузі | F5: Частка у надходженнях від сплати ПДФО в бюджет ТГ, що надійшли від ІТ-підприємств | G5: % | H5: Базовий | I5: Обов'язковий для вимірювання | J5: Кількісні дані | K5: 0.05 | L5: 0.15384615 | M5: 0.15384615
B6: Цифрова економіка в ТГ | C6: Розвиток підприємств ІТ-сектору в ТГ | D6: A.1.3 | E6: % виручки від експорту послуг і товарів, яку отримали СПД, що працюють в ІТ-галузі, від загальної виручки від експорту послуг і товарів (в ТГ) | G6: % | I6: На майбутнє вимірювання | J6: Кількісні дані | L6: 0 | M6: 0
B7: Цифрова економіка в ТГ | C7: Розвиток підприємств ІТ-сектору в ТГ | D7: A.1.4 | E7: % виручки від внутрішнього споживання послуг і товарів, яку отримали СПД, що працюють в ІТ-галузі, від загальної виручки від послуг і товарів внутрішнього споживання (статистика) | G7: % | I7: На майбутнє вимірювання | J7: Кількісні дані | L7: 0 | M7: 0
B8: Цифрова економіка в ТГ | C8: Розвиток підприємств ІТ-сектору в ТГ | D8: A.1.5 | E8: % у надходженнях від сплати єдиного податку в бюджет ТГ, що надійшли від CПД з КВЕД ІТ-галузі | F8: Частка у надходженнях від сплати єдиного податку в бюджет ТГ, що надійшли від CПД з КВЕД ІТ-галузі | G8: % | H8: Базовий | I8: Обов'язковий для вимірювання | J8: Кількісні дані | K8: 0.1 | L8: 0.15384615 | M8: 0.15384615
B9: Цифрова економіка в ТГ | C9: Розвиток підприємств ІТ-сектору в ТГ | D9: A.1.6 | E9: % нових робочих місць, створених на підприємствах ІТ-галузі від загальної кількості нових робочих місць за звітній період | G9: % | H9: Базовий | I9: Обов'язковий для вимірювання | J9: Кількісні дані | K9: 0.1 | L9: 0.14285714 | M9: 0.14285714
B10: Цифрова економіка в ТГ | C10: Розвиток підприємств ІТ-сектору в ТГ | D10: A.1.7 | E10: Відношення середньої заробітної плати в ІТ-галузі у ТГ до середньої заробітної плати в ТГ | F10: Відношення середньої заробітної плати в ІТ-галузі у ТГ до середньої заробітної плати в ТГ | G10: % | H10: Базовий | I10: Обов'язковий для вимірювання | J10: Кількісні дані | K10: 1.5 | L10: 0.13186813 | M10: 0.13186813
B11: Цифрова економіка в ТГ | C11: Розвиток підприємств ІТ-сектору в ТГ | D11: A.1.8 | E11: Відношення середньої заробітної плати в ІТ-галузі у ТГ до середньої заробітної плати в ІТ-галузі в Україні | G11: % | H11: Базовий | I11: Обов'язковий для вимірювання | J11: Кількісні дані | K11: 1.2 | L11: 0.13186813 | M11: 0.13186813
B12: Цифрова економіка в ТГ | C12: Розвиток підприємств ІТ-сектору в ТГ | D12: A.1.9 | E12: Частка жінок на керівних посадах у підприємствах ІТ-галузі в ТГ | G12: % | I12: На майбутнє вимірювання | J12: Кількісні дані | K12: 0,5 | L12: 0 | M12: 0
B13: Цифрова економіка в ТГ | C13: Розвиток підприємств ІТ-сектору в ТГ | D13: A.1.10 | E13: Частка локальних ІТ підприємств, залучених до програми Дія Сіті, в загальній кількості ІТ підприємств | G13: % | H13: Базовий | I13: Обов'язковий для вимірювання | J13: Кількісні дані | K13: 0.005 | L13: 0.13186813 | M13: 0.13186813
B14: Цифрова економіка в ТГ | C14: Розвиток підприємств ІТ-сектору в ТГ | D14: A.1.11 | E14: % стартапів, заснованих на основі використання відкритих даних, до загальної кількості стартапів | G14: % | I14: На майбутнє вимірювання | J14: Кількісні дані | L14: 0 | M14: 0
B15: Цифрова економіка в ТГ | C15: Привабливість для інвестицій в галузь ІТ | D15: A.2.1 | E15: % залучених капітальних інвестицій в ІТ-галузі від загального обсягу інвестицій у підприємства у ТГ | G15: % | I15: На майбутнє вимірювання | J15: Кількісні дані | L15: 0 | M15: 0
B16: Цифрова економіка в ТГ | C16: Привабливість для інвестицій в галузь ІТ | D16: A.2.2 | E16: Кількість робочих місць в ІТ-хабах, які можуть орендувати/де можуть працювати ІТ-спеціалісти, на 1 тис населення | F16: Кількість робочих місць в ІТ-хабах, що можуть орендувати/де можуть працювати ІТ-спеціалісти, на 1 тис населення | G16: од/1000 населення | H16: Базовий | I16: Обов'язковий для вимірювання | J16: Кількісні дані | K16: 2 | L16: 0.19791667 | M16: 0.5
B17: Цифрова економіка в ТГ | C17: Привабливість для інвестицій в галузь ІТ | D17: A.2.3 | E17: Наявність та актуальність інформації про інвестиційні об'єкти ТГ | F17: Наявність та актуальність інформації про інвестиційні об'єкти ТГ | G17: Бал | H17: Базовий | I17: Обов'язковий для вимірювання | J17: Якісні дані | K17: 1 | L17: 0.19791667 | M17: 0.5
B18: Цифрова економіка в ТГ | C18: Привабливість для інвестицій в галузь ІТ | D18: A.2.4 | E18: % випускників вищих навчальних закладів (крім коледжів) за спеціальностями в ІТ-галузі від загальної кількості випускників | F18: Частка випускників ЗВО (крім коледжів) за спеціальностями в ІТ-галузі від загальної кількості випускників | G18: % | H18: Розширений | I18: Обов'язковий для вимірювання | J18: Кількісні дані | K18: 0.1 | L18: 0.33333333 | M18: 0
B19: Цифрова економіка в ТГ | C19: Привабливість для інвестицій в галузь ІТ | D19: A.2.5 | E19: % випускників коледжів за спеціальностями в ІТ-галузі від загальної кількості випускників | F19: Частка випускників коледжів за спеціальностями в ІТ-галузі від загальної кількості випускників | G19: % | H19: Розширений | I19: Обов'язковий для вимірювання | J19: Кількісні дані | K19: 0.1 | L19: 0.27083333 | M19: 0
B20: Цифрова економіка в ТГ | C20: Цифрові технології для бізнесу | D20: A.3.1 | E20: % заявок на реєстрацію СПД, поданих онлайн | G20: % | I20: На майбутнє вимірювання | J20: Кількісні дані | K20: 1 | L20: 0 | M20: 0
B21: Цифрова економіка в ТГ | C21: Цифрові технології для бізнесу | D21: A.3.2 | E21: % СПД, які подають звіти онлайн | G21: % | H21: Базовий | I21: На майбутнє вимірювання | J21: Кількісні дані | K21: 1 | L21: 0 | M21: 0
B22: Цифрова економіка в ТГ | C22: Цифрові технології для бізнесу | D22: A.3.3 | E22: % онлайн-послуг ОМС для бізнесу від загальної кількості послуг (послуги, суб'єктом надання яких є ОМС, комунальні підприємства, заклади) | F22: Частка онлайн-послуг ОМС для бізнесу від загальної кількості послуг | G22: % | H22: Базовий | I22: Обов'язковий для вимірювання | J22: Кількісні дані | K22: 1 | L22: 0.5 | M22: 0.5
B23: Цифрова економіка в ТГ | C23: Цифрові технології для бізнесу | D23: A.3.4 | E23: Створено центр підтримки підприємців Дія.Бізнес | F23: Створено центр Дія.Бізнес | G23: Балів | H23: Базовий | I23: Обов'язковий для вимірювання | J23: Якісні дані | K23: 1 | L23: 0.5 | M23: 0.5
B24: Розвиток цифрових навичок населення | C24: Розвиток цифрової грамотності населення | D24: В.1.2 | E24: % населення, що має застосунок Дія | G24: % | I24: На майбутнє вимірювання | J24: Кількісні дані | K24: 0.8 | L24: 0 | M24: 0
B25: Розвиток цифрових навичок населення | C25: Розвиток цифрової грамотності населення | D25: В.1.3 | E25: % населення у громаді, що використовує смартфони та/або планшети | G25: % | I25: На майбутнє вимірювання | J25: Кількісні дані | L25: 0 | M25: 0
B26: Розвиток цифрових навичок населення | C26: Розвиток цифрової грамотності населення | D26: В.1.4 | E26: % жителів поважного віку (60+ років), які пройшли навчання з цифрової грамотності / гігієни від загальної чисельності наявного населення поважного віку | G26: % | H26: Базовий | I26: Обов'язковий для вимірювання | J26: Кількісні дані | K26: 0.05 | L26: 0.070588235 | M26: 0.070588235
B27: Розвиток цифрових навичок населення | C27: Розвиток цифрової грамотності населення | D27: В.1.5 | E27: % середньозваженого значення балів Цифрограм (1.0 та 2.0) осіб, які пройшли тестування в застосунку Цифрограм 1.0 та 2.0 протягом звітного періоду, від максимальної кількості балів Цифрограм (1.0 та 2.0) | F27: Кількість осіб у ТГ, які пройшли тестування Цифрограм 1.0 та 2.0 на 1 тис. населення в ТГ | G27: % | I27: На майбутнє вимірювання | J27: Кількісні дані | K27: 0.75 | L27: 0 | M27: 0
B28: Розвиток цифрових навичок населення | C28: Розвиток цифрової грамотності населення | D28: В.1.6 | E28: Кількість осіб у ТГ, які пройшли тестування в застосунку Цифрограм 1.0 та 2.0/на 1000 населення в ТГ | G28: Осіб/1000 осіб | H28: Базовий | I28: Обов'язковий для вимірювання | J28: Кількісні дані | K28: 50 | L28: 0.16470588 | M28: 0.16470588
B29: Розвиток цифрових навичок населення | C29: Розвиток цифрової грамотності населення | D29: В.1.7 | E29: % жителів громади, які отримали ID-картки, від загальної кількості жителів ТГ відповідного віку | G29: % | H29: Базовий | I29: Обов'язковий для вимірювання | J29: Кількісні дані | K29: 1 | L29: 0.43529412 | M29: 0.43529412
B30: Розвиток цифрових навичок населення | C30: Розвиток цифрової грамотності населення | D30: В.1.8 | E30: % жителів ТГ, які зареєстрували своє місце проживання через портал Дія, від загальної кількості реєстрацій місць проживання за звітний період | G30: % | I30: На майбутнє вимірювання | J30: Кількісні дані | K30: 0.5 | L30: 0 | M30: 0
B31: Розвиток цифрових навичок населення | C31: Розвиток цифрової грамотності населення | D31: В.1.9 | E31: % дітей, зареєстрованих через єМалятко, від загальної кількості новонароджених | G31: % | H31: Базовий | I31: Обов'язковий для вимірювання | J31: Кількісні дані | K31: 1 | L31: 0.32941176 | M31: 0.32941176
B32: Розвиток цифрових навичок населення | C32: Розвиток талантів в галузі ІКТ | D32: В.2.1 | E32: Наявність школярів (6-11 класів), які стали призерами (1-3 місце) всеукраїнських олімпіад (4 етапу) з Математики та Інформатики | F32: Наявність школярів (6-11 класів), які стали призерами (1-3 місце) всеукраїнських олімпіад (4 етапу) з математики та інформатики | G32: Балів | H32: Базовий | I32: Обов'язковий для вимірювання | J32: Якісні дані | K32: 1 | L32: 0.33333333 | M32: 0.33333333
B33: Розвиток цифрових навичок населення | C33: Розвиток талантів в галузі ІКТ | D33: В.2.2 | E33: Кількість школярів (6-11 класів), які стали призерами (1-3 місце) олімпіад (2 та 3 етапів) з Математики та Інформатики, на 1000 тисячу школярів (6-11 класів) в ТГ | F33: Кількість школярів (6-11 класів), які стали призерами (1-3 місце) олімпіад (2 та 3 етапів) з математики та інформатики, на 1 тис тисячу школярів (6-11 класів) в ТГ | G33: Осіб/1000 осіб | H33: Базовий | I33: Обов'язковий для вимірювання | J33: Кількісні дані | K33: 5 | L33: 0.33333333 | M33: 0.33333333
B34: Розвиток цифрових навичок населення | C34: Розвиток талантів в галузі ІКТ | D34: В.2.3 | E34: Кількість хабів цифрової освіти на 10 000 осіб | G34: Хабів/10 000 осіб | H34: Базовий | I34: Обов'язковий для вимірювання | J34: Кількісні дані | K34: 1 | L34: 0.33333333 | M34: 0.33333333
B35: Цифрова інфраструктура в ТГ | C35: Якість та доступність цифрової інфраструктури | D35: С.1.1 | E35: % соціальних об'єктів ТГ, підключених до волоконно-оптичних мереж | F35: Частка соціальних об'єктів ТГ, підключених до волоконно-оптичних мереж | G35: % | H35: Базовий | I35: Обов'язковий для вимірювання | J35: Кількісні дані | K35: 1 | L35: 0.28776978 | M35: 0.28776978
B36: Цифрова інфраструктура в ТГ | C36: Якість та доступність цифрової інфраструктури | D36: С.1.2 | E36: % підрозділів та віддалених робочих місць ЦНАП, підключених до системи онлайн-моніторингу й оцінювання якості послуг Порталу Дія | F36: Частка підрозділів та віддалених робочих місць ЦНАП, підключених до системи онлайн-моніторингу й оцінювання якості послуг Порталу Дія | G36: % | H36: Базовий | I36: Обов'язковий для вимірювання | J36: Кількісні дані | K36: 1 | L36: 0.22302158 | M36: 0.22302158
B37: Цифрова інфраструктура в ТГ | C37: Якість та доступність цифрової інфраструктури | D37: С.1.3 | E37: % посадових осіб, які мають службовий персональний комп'ютер, від загальної кількості посадових осіб ОМС | F37: Частка посадових осіб, які мають службовий персональний комп'ютер, від загальної кількості посадових осіб ОМС | G37: % | H37: Базовий | I37: Обов'язковий для вимірювання | J37: Кількісні дані | K37: 1 | L37: 0.20143885 | M37: 0.20143885
B38: Цифрова інфраструктура в ТГ | C38: Якість та доступність цифрової інфраструктури | D38: С.1.4 | E38: % комп'ютерної техніки в закладах освіти, вік якої менше 7 років | F38: Частка комп'ютерної техніки в закладах освіти віком до 7 років | G38: % | H38: Базовий | I38: Обов'язковий для вимірювання | J38: Кількісні дані | K38: 1 | L38: 0.086330935 | M38: 0.086330935
B39: Цифрова інфраструктура в ТГ | C39: Якість та доступність цифрової інфраструктури | D39: С.1.5 | E39: % персональних комп'ютерів та серверів у ОМС віком до 7 років | F39: Частка персональних комп'ютерів та серверів у ОМС віком до 7 років | G39: % | H39: Базовий | I39: Обов'язковий для вимірювання | J39: Кількісні дані | K39: 1 | L39: 0.20143885 | M39: 0.20143885
B40: Цифрова інфраструктура в ТГ | C40: Кібербезпека | D40: С.2.1 | E40: Управління кіберінцидентами | G40: Балів | I40: На майбутнє вимірювання | J40: Якісні дані | L40: 0 | M40: 0
B41: Цифрова інфраструктура в ТГ | C41: Кібербезпека | D41: С.2.2 | E41: % посадових осіб ОМС, які пройшли навчання (підвищення кваліфікації) за програмами з кібербезпеки й кібергігієни, від загальної кількості посадових осіб ОМС | F41: Частка посадових осіб ОМС, які пройшли навчання (підвищення кваліфікації) за програмами з кібербезпеки й кібергігієни, від загальної кількості посадових осіб ОМС | G41: % | H41: Базовий | I41: Обов'язковий для вимірювання | J41: Кількісні дані | K41: 0.5 | L41: 0.22077922 | M41: 0.22077922
B42: Цифрова інфраструктура в ТГ | C42: Кібербезпека | D42: С.2.3 | E42: % комп'ютерної техніки в ОМС, на якій регулярно (1 раз на квартал) проводиться контроль оновлень ПЗ до останньої версії | F42: Частка комп'ютерної техніки в ОМС, на якій 1 раз на квартал проводиться контроль оновлень ПЗ до останньої версії | G42: % | H42: Базовий | I42: Обов'язковий для вимірювання | J42: Кількісні дані | K42: 1 | L42: 0.22077922 | M42: 0.22077922
...

Sheet Паспорт Iндикаторiв
B3: Група | C3: Підгрупа | D3: # Індика-тора | E3: Назва індикатора | F3: Фінальна назва Індикатора на ДЦГ | G3: Одиниці вимірювання індикатора (ОВ) | H3: Структура індексу | I3: Вид індикатора | J3: Характер даних | K3: Цільове значення індикатора | L3: Вага індикатора Розширений | M3: Вага індикатора Базовий | O3: # Показника | P3: Назва Показника | Q3: Присвоєння балів (в роботі) | R3: Формула розрахунку та ОВ | T3: Визначення складових і термінів | U3: Періодичність вимірювання | V3: Документ, що лежить в основі індикатора | W3: Джерело даних Показника
B4: Цифрова економіка в ТГ | C4: Розвиток підприємств ІТ-сектору в ТГ | D4: A.1.1 | E4: % СПД із КВЕДами ІТ-галузі у загальній кількості тих, які були відкриті та/або переміщені з інших ТГ протягом звітного періоду | G4: % | H4: Базовий | I4: На майбутнє вимірювання | J4: Кількісні дані | K4: 0.15 | L4: =VLOOKUP(D4,'Перелік Iндикаторiв'!$D$4:$M$99,8,FALSE) -> 0.05 | M4: =VLOOKUP(D4,'Перелік Iндикаторiв'!$D$4:$M$99,9,FALSE) -> 0.15384615 | O4: A.1.1.1 | P4: Кількість СПД в ІТ-галузі, які були відкриті та/або переміщені з інших ТГ (ОВ: СПД) | Q4: Бал індикатора присвоюється пропорційно до розрахованого значення у відношенні до цільового з кроком 1 бал, де 100 - максимальний бал, коли розраховане значення дорівнює цільовому, 0 - мінімальний бал | R4: Формула розрахунку - [((Показник 1.1-Показник 1.2)/Показник 1.3)*100%], де Показник 1.1 - Кількість СПД в ІТ-галузі, які були відкриті та/або переміщені з інших ТГ, шт Показник 1.2 - Кількість СПД в ІТ-галузі, які припинили діяльність в ТГ, шт Показник 1.3 - Загальна кількість СПД в ІТ-галузі в ТГ станом на кінець звітного року, шт | T4: Суб'єкти підприємницької діяльності (СПД) в ІТ-галузі, зареєстровані на території ТГ – кількість СПД, що на території ТГ отримали послугу державної реєстрації суб'єкта підприємницької діяльності відповідно до Розділу 4 Закону України "Про державну реєстрацію юридичних осіб, фізичних осіб-підприємців та громадських формувань" і зазначили основним видом діяльності один із нижчезазначених КВЕД: 62.01 Комп’ютерне програмування; 62.02 Консультування з питань інформатизації; 62.09 Інша діяльність у сфері інформаційних технологій і комп'ютерних систем. 58.21 Видання комп'ютерних ігор; 58.29 Видання іншого програмного забезпечення; 63.11 Оброблення даних, розміщення інформації на веб-вузлах і пов’язана з ними діяльність; 18.20 Тиражування звуко-, відеозаписів і програмного забезпечення; 47.41 Роздрібна торгівля комп’ютерами, периферійним устаткуванням і програмним забезпеченням у спеціалізованих магазинах; | U4: за рік | V4: Закону України "Про державну реєстрацію юридичних осіб, фізичних осіб-підприємців та громадських формувань" https://zakon.rada.gov.ua/laws/show/755-15#Text | W4: Дані Державної податкової служби
B5: Цифрова економіка в ТГ | C5: Розвиток підприємств ІТ-сектору в ТГ | D5: A.1.1 | G5: % | H5: Базовий | I5: На майбутнє вимірювання | J5: Кількісні дані | K5: 0.15 | L5: =VLOOKUP(D5,'Перелік Iндикаторiв'!$D$4:$M$99,8,FALSE) -> 0.05 | M5: =VLOOKUP(D5,'Перелік Iндикаторiв'!$D$4:$M$99,9,FALSE) -> 0.15384615 | O5: A.1.1.2 | P5: Кількість СПД в ІТ-галузі, які припинили діяльність в ТГ (ОВ: СПД) | Q5: Бал індикатора присвоюється пропорційно до розрахованого значення у відношенні до цільового з кроком 1 бал, де 100 - максимальний бал, коли розраховане значення дорівнює цільовому, 0 - мінімальний бал | R5: Формула розрахунку - [((Показник 1.1-Показник 1.2)/Показник 1.3)*100%], де Показник 1.1 - Кількість СПД в ІТ-галузі, які були відкриті та/або переміщені з інших ТГ, шт Показник 1.2 - Кількість СПД в ІТ-галузі, які припинили діяльність в ТГ, шт Показник 1.3 - Загальна кількість СПД в ІТ-галузі в ТГ станом на кінець звітного року, шт | T5: Суб'єкти підприємницької діяльності (окрім державних та комунальних підприємств), зареєстровані на території ТГ, що припинили діяльність – кількість СПД на території ТГ, які отримали послугу з припинення підприємницької діяльності відповідно до Розділу 4 Закону України "Про державну реєстрацію юридичних осіб, фізичних осіб-підприємців та громадських формувань" і зазначили основним видом діяльності один із нижчезазначених КВЕД: 62.01 Комп’ютерне програмування; 62.02 Консультування з питань інформатизації; 62.09 Інша діяльність у сфері інформаційних технологій і комп'ютерних систем. 58.21 Видання комп'ютерних ігор; 58.29 Видання іншого програмного забезпечення; 63.11 Оброблення даних, розміщення інформації на веб-вузлах і пов’язана з ними діяльність; 18.20 Тиражування звуко-, відеозаписів і програмного забезпечення; 47.41 Роздрібна торгівля комп’ютерами, периферійним устаткуванням і програмним забезпеченням у спеціалізованих магазинах; | U5: за рік | V5: Закону України "Про державну реєстрацію юридичних осіб, фізичних осіб-підприємців та громадських формувань" https://zakon.rada.gov.ua/laws/show/755-15#Text | W5: Дані Державної податкової служби
B6: Цифрова економіка в ТГ | C6: Розвиток підприємств ІТ-сектору в ТГ | D6: A.1.1 | G6: % | H6: Базовий | I6: На майбутнє вимірювання | J6: Кількісні дані | K6: 0.15 | L6: =VLOOKUP(D6,'Перелік Iндикаторiв'!$D$4:$M$99,8,FALSE) -> 0.05 | M6: =VLOOKUP(D6,'Перелік Iндикаторiв'!$D$4:$M$99,9,FALSE) -> 0.15384615 | O6: A.1.1.3 | P6: Загальна кількість СПД в ІТ-галузі в ТГ (ОВ: СПД) | Q6: Бал індикатора присвоюється пропорційно до розрахованого значення у відношенні до цільового з кроком 1 бал, де 100 - максимальний бал, коли розраховане значення дорівнює цільовому, 0 - мінімальний бал | R6: Формула розрахунку - [((Показник 1.1-Показник 1.2)/Показник 1.3)*100%], де Показник 1.1 - Кількість СПД в ІТ-галузі, які були відкриті та/або переміщені з інших ТГ, шт Показник 1.2 - Кількість СПД в ІТ-галузі, які припинили діяльність в ТГ, шт Показник 1.3 - Загальна кількість СПД в ІТ-галузі в ТГ станом на кінець звітного року, шт | T6: Суб'єкти підприємницької діяльності в ІТ-галузі – вітчизняні та іноземні юридичні особи, а також фізичні особи-підприємці, які провадять діяльність в Україні та зазначили основним видом діяльності один із нижчезазначених КВЕД: 62.01 Комп’ютерне програмування; 62.02 Консультування з питань інформатизації; 62.09 Інша діяльність у сфері інформаційних технологій і комп'ютерних систем. 58.21 Видання комп'ютерних ігор; 58.29 Видання іншого програмного забезпечення; 63.11 Оброблення даних, розміщення інформації на веб-вузлах і пов’язана з ними діяльність; 18.20 Тиражування звуко-, відеозаписів і програмного забезпечення; 47.41 Роздрібна торгівля комп’ютерами, периферійним устаткуванням і програмним забезпеченням у спеціалізованих магазинах; | U6: станом на 01.01.2022 | V6: Закону України "Про державну реєстрацію юридичних осіб, фізичних осіб-підприємців та громадських формувань" https://zakon.rada.gov.ua/laws/show/755-15#Text | W6: Дані Державної податкової служби
B7: Цифрова економіка в ТГ | C7: Розвиток підприємств ІТ-сектору в ТГ | D7: A.1.2 | E7: % у надходженнях від сплати ПДФО в бюджет ТГ, що надійшли від підприємств, що працюють в ІТ-галузі | F7: Частка у надходженнях від сплати ПДФО в бюджет ТГ, що надійшли від ІТ-підприємств | G7: % | H7: Базовий | I7: Обов'язковий для вимірювання | J7: Кількісні дані | K7: 0.15 | L7: =VLOOKUP(D7,'Перелік Iндикаторiв'!$D$4:$M$99,8,FALSE) -> 0.05 | M7: =VLOOKUP(D7,'Перелік Iндикаторiв'!$D$4:$M$99,9,FALSE) -> 0.15384615 | O7: A.1.2.1 | P7: Обсяг надходжень до бюджету ТГ від сплати ПДФО підприємствами ІТ-галузі за звітний рік (ОВ: грн) | Q7: Бал індикатора присвоюється пропорційно до розрахованого значення у відношенні до цільового з кроком 1 бал, де 100 - максимальний бал, коли розраховане значення дорівнює цільовому, 0 - мінімальний бал | R7: Формула розрахунку - [((Показник 1.1/Показник 1.2)*100%], де Показник 1.1 – обсяг надходжень до бюджету ТГ від сплати ПДФО підприємствами ІТ-галузі за звітний рік, грн Показник 1.2 - Загальний обсяг надходжень до бюджету ТГ від сплати ПДФО за звітний рік, грн | T7: Обсяг надходжень до бюджету ТГ від сплати ПДФО підприємствами ІТ-галузі – обсяг коштів, що надійшли до бюджету ТГ від сплати суб'єктами податку на доходи фізичних осіб суб'єктами підприємницької діяльності, основною діяльністю яких є такі КВЕД: 62.01 Комп’ютерне програмування; 62.02 Консультування з питань інформатизації; 62.09 Інша діяльність у сфері інформаційних технологій і комп'ютерних систем. 58.21 Видання комп'ютерних ігор; 58.29 Видання іншого програмного забезпечення; 63.11 Оброблення даних, розміщення інформації на веб-вузлах і пов’язана з ними діяльність; 18.20 Тиражування звуко-, відеозаписів і програмного забезпечення; 47.41 Роздрібна торгівля комп’ютерами, периферійним устаткуванням і програмним забезпеченням у спеціалізованих магазинах; Обсяг надходжень від сплати ПДФО – обсяг коштів, що надійшли до бюджету ТГ від сплати суб'єктами податку на доходи фізичних осіб за такими кодами класифікації доходів: 11010100, 11010200, 11010400, 11010500, 11010600, 11010700, 11010900. | U7: за рік | V7: Бюджетний кодекс України https://zakon.rada.gov.ua/laws/show/2456-17#Text Наказ Міністерства фінансів "Про бюджетну класифікацію" №11 від 14 січня 2011 https://zakon.rada.gov.ua/rada/show/v0011201-11#Text | W7: Дані Державної податкової служби
B8: Цифрова економіка в ТГ | C8: Розвиток підприємств ІТ-сектору в ТГ | D8: A.1.2 | E8: % у надходженнях від сплати ПДФО в бюджет ТГ, що надійшли від підприємств, що працюють в ІТ-галузі | G8: % | H8: Базовий | I8: Обов'язковий для вимірювання | J8: Кількісні дані | K8: 0.15 | L8: =VLOOKUP(D8,'Перелік Iндикаторiв'!$D$4:$M$99,8,FALSE) -> 0.05 | M8: =VLOOKUP(D8,'Перелік Iндикаторiв'!$D$4:$M$99,9,FALSE) -> 0.15384615 | O8: A.1.2.2 | P8: Загальний обсяг надходжень до бюджету ТГ від сплати ПДФО за звітний рік (ОВ: грн) | Q8: Бал індикатора присвоюється пропорційно до розрахованого значення у відношенні до цільового з кроком 1 бал, де 100 - максимальний бал, коли розраховане значення дорівнює цільовому, 0 - мінімальний бал | R8: Формула розрахунку - [((Показник 1.1/Показник 1.2)*100%], де Показник 1.1 – обсяг надходжень до бюджету ТГ від сплати ПДФО підприємствами ІТ-галузі за звітний рік, грн Показник 1.2 - Загальний обсяг надходжень до бюджету ТГ від сплати ПДФО за звітний рік, грн | T8: Обсяг надходжень від сплати ПДФО – обсяг коштів, що надійшли до бюджету ТГ від сплати суб'єктами податку на доходи фізичних осіб за такими кодами класифікації доходів: 11010100, 11010200, 11010400, 11010500, 11010600, 11010700, 11010900. | U8: за рік | V8: Бюджетний кодекс України https://zakon.rada.gov.ua/laws/show/2456-17#Text Наказ Міністерства фінансів "Про бюджетну класифікацію" №11 від 14 січня 2011 https://zakon.rada.gov.ua/rada/show/v0011201-11#Text | W8: Дані Державної податкової служби
B9: Цифрова економіка в ТГ | C9: Розвиток підприємств ІТ-сектору в ТГ | D9: A.1.3 | E9: % виручки від експорту послуг і товарів, яку отримали СПД, що працюють в ІТ-галузі, від загальної виручки від експорту послуг і товарів (в ТГ) | G9: % | I9: На майбутнє вимірювання | J9: Кількісні дані | L9: =VLOOKUP(D9,'Перелік Iндикаторiв'!$D$4:$M$99,8,FALSE) -> 0 | M9: =VLOOKUP(D9,'Перелік Iндикаторiв'!$D$4:$M$99,9,FALSE) -> 0 | O9: A.1.3.1 | P9: Обсяг доходу від експорту товарів і послуг, отриманого СПД ІТ-галузі, зареєстрованими в ТГ, за звітний рік (ОВ: грн) | Q9: Бал індикатора присвоюється пропорційно до розрахованого значення у відношенні до цільового з кроком 1 бал, де 100 - максимальний бал, коли розраховане значення дорівнює цільовому, 0 - мінімальний бал | R9: Формула розрахунку - [((Показник 1.1/Показник 1.2)*100%], де Показник 1.1 – обсяг доходу від експорту товарів і послуг, отриманого СПД ІТ-галузі, зареєстрованими в ТГ, за звітний рік, грн Показник 1.2 - Загальний обсяг доходу від експорту товарів і послуг, отриманого СПД ІТ-галузі, зареєстрованими в ТГ, за звітний рік, грн | T9: Дохід від експорту ІТ-галузі – вартість операцій із надання товарів і послуг резидентами, зареєстрованими у ТГ, основною діяльністю яких є такі КВЕД: 62.01 Комп’ютерне програмування; 62.02 Консультування з питань інформатизації; 62.09 Інша діяльність у сфері інформаційних технологій і комп'ютерних систем. 58.21 Видання комп'ютерних ігор; 58.29 Видання іншого програмного забезпечення; 63.11 Оброблення даних, розміщення інформації на веб-вузлах і пов’язана з ними діяльність; 18.20 Тиражування звуко-, відеозаписів і програмного забезпечення; 47.41 Роздрібна торгівля комп’ютерами, периферійним устаткуванням і програмним забезпеченням у спеціалізованих магазинах; нерезиденту згідно з договорами (контрактами) або в усній формі договору за датою їх фактичного надання за принципом нарахування (за виписаними рахунками) | U9: за рік | V9: Наказ Державної служби статистики України 03.10.2014 № 284 https://ukrstat.gov.ua/metod_polog/metod_doc/2014/284/284_2014.htm | W9: Дані структурного підрозділу ОМС
B10: Цифрова економіка в ТГ | C10: Розвиток підприємств ІТ-сектору в ТГ | D10: A.1.3 | E10: % виручки від експорту послуг і товарів, яку отримали СПД, що працюють в ІТ-галузі, від загальної виручки від експорту послуг і товарів (в ТГ) | G10: % | I10: На майбутнє вимірювання | J10: Кількісні дані | L10: =VLOOKUP(D10,'Перелік Iндикаторiв'!$D$4:$M$99,8,FALSE) -> 0 | M10: =VLOOKUP(D10,'Перелік Iндикаторiв'!$D$4:$M$99,9,FALSE) -> 0 | O10: A.1.3.2 | P10: Загальний обсяг доходу від експорту товарів і послуг, отриманого СПД, зареєстрованими в ТГ, за звітний рік (ОВ: грн) | Q10: Бал індикатора присвоюється пропорційно до розрахованого значення у відношенні до цільового з кроком 1 бал, де 100 - максимальний бал, коли розраховане значення дорівнює цільовому, 0 - мінімальний бал | R10: Формула розрахунку - [((Показник 1.1/Показник 1.2)*100%], де Показник 1.1 – обсяг доходу від експорту товарів і послуг, отриманого СПД ІТ-галузі, зареєстрованими в ТГ, за звітний рік, грн Показник 1.2 - Загальний обсяг доходу від експорту товарів і послуг, отриманого СПД ІТ-галузі, зареєстрованими в ТГ, за звітний рік, грн | T10: Дохід від експорту – вартість операцій із надання товарів і послуг резидентом, зареєстрованим у ТГ, нерезиденту згідно з договорами (контрактами) або в усній формі договору за датою їх фактичного надання за принципом нарахування (за виписаними рахунками) | U10: за рік | V10: Наказ Державної служби статистики України 03.10.2014 № 284 https://ukrstat.gov.ua/metod_polog/metod_doc/2014/284/284_2014.htm | W10: Дані структурного підрозділу ОМС
B11: Цифрова економіка в ТГ | C11: Розвиток підприємств ІТ-сектору в ТГ | D11: A.1.4 | E11: % виручки від внутрішнього споживання послуг і товарів, яку отримали СПД, що працюють в ІТ-галузі, від загальної виручки від послуг і товарів внутрішнього споживання (статистика) | G11: % | I11: На майбутнє вимірювання | J11: Кількісні дані | L11: =VLOOKUP(D11,'Перелік Iндикаторiв'!$D$4:$M$99,8,FALSE) -> 0 | M11: =VLOOKUP(D11,'Перелік Iндикаторiв'!$D$4:$M$99,9,FALSE) -> 0 | O11: A.1.4.1 | P11: Обсяг доходу від внутрішнього споживання послуг і товарів, отриманого СПД ІТ-галузі, зареєстрованими в ТГ, за звітний рік (ОВ: грн) | Q11: Бал індикатора присвоюється пропорційно до розрахованого значення у відношенні до цільового з кроком 1 бал, де 100 - максимальний бал, коли розраховане значення дорівнює цільовому, 0 - мінімальний бал | R11: Формула розрахунку - [((Показник 1.1/Показник 1.2)*100%], де Показник 1.1 – обсяг доходу від внутрішнього споживання послуг і товарів, отриманого СПД ІТ-галузі, зареєстрованими в ТГ, за звітний рік, грн Показник 1.2 - Загальний обсяг доходу від внутрішнього споживання товарів і послуг, отриманого СПД, зареєстрованими в ТГ, за звітний рік, грн | T11: Дохід від внутрішнього споживання ІТ-галузі – вартість операцій із надання товарів і послуг резидентом, зареєстрованим у ТГ, основною діяльністю якого є нижченаведені КВЕД: 62.01 Комп’ютерне програмування; 62.02 Консультування з питань інформатизації; 62.09 Інша діяльність у сфері інформаційних технологій і комп'ютерних систем. 58.21 Видання комп'ютерних ігор; 58.29 Видання іншого програмного забезпечення; 63.11 Оброблення даних, розміщення інформації на веб-вузлах і пов’язана з ними діяльність; 18.20 Тиражування звуко-, відеозаписів і програмного забезпечення; 47.41 Роздрібна торгівля комп’ютерами, периферійним устаткуванням і програмним забезпеченням у спеціалізованих магазинах; іншому резиденту згідно з договорами (контрактами) або в усній формі договору за датою їх фактичного надання за принципом нарахування (за виписаними рахунками). | U11: за рік | V11: Потребує визначення в законодавстві | W11: Дані структурного підрозділу ОМС
B12: Цифрова економіка в ТГ | C12: Розвиток підприємств ІТ-сектору в ТГ | D12: A.1.4 | E12: % виручки від внутрішнього споживання послуг і товарів, яку отримали СПД, що працюють в ІТ-галузі, від загальної виручки від послуг і товарів внутрішнього споживання (статистика) | G12: % | I12: На майбутнє вимірювання | J12: Кількісні дані | L12: =VLOOKUP(D12,'Перелік Iндикаторiв'!$D$4:$M$99,8,FALSE) -> 0 | M12: =VLOOKUP(D12,'Перелік Iндикаторiв'!$D$4:$M$99,9,FALSE) -> 0 | O12: A.1.4.2 | P12: Загальний обсяг доходу від внутрішнього споживання товарів і послуг, отриманого СПД, зареєстрованими в ТГ, за звітний рік (ОВ: грн) | Q12: Бал індикатора присвоюється пропорційно до розрахованого значення у відношенні до цільового з кроком 1 бал, де 100 - максимальний бал, коли розраховане значення дорівнює цільовому, 0 - мінімальний бал | R12: Формула розрахунку - [(Показник 1.1/Показник 1.2)*100%], де Показник 1.1 – обсяг доходу від внутрішнього споживання послуг і товарів, отриманого СПД ІТ-галузі, зареєстрованими в ТГ, за звітний рік, грн Показник 1.2 - Загальний обсяг доходу від внутрішнього споживання товарів і послуг, отриманий СПД, зареєстрованими в ТГ за звітний рік, грн | T12: Дохід від внутрішнього споживання – вартість операцій із надання товарів і послуг резидентом, зареєстрованим у ТГ, іншому резиденту згідно з договорами (контрактами) або в усній формі договору за датою їх фактичного надання за принципом нарахування (за виписаними рахунками). | U12: за рік | V12: Потребує визначення в законодавстві | W12: Дані структурного підрозділу ОМС
B13: Цифрова економіка в ТГ | C13: Розвиток підприємств ІТ-сектору в ТГ | D13: A.1.5 | E13: % у надходженнях від сплати єдиного податку в бюджет ТГ, що надійшли від CПД з КВЕД ІТ-галузі | F13: Частка у надходженнях від сплати єдиного податку в бюджет ТГ, що надійшли від CПД з КВЕД ІТ-галузі | G13: % | H13: Базовий | I13: Обов'язковий для вимірювання | J13: Кількісні дані | K13: 0.1 | L13: =VLOOKUP(D13,'Перелік Iндикаторiв'!$D$4:$M$99,8,FALSE) -> 0.1 | M13: =VLOOKUP(D13,'Перелік Iндикаторiв'!$D$4:$M$99,9,FALSE) -> 0.15384615 | O13: A.1.5.1 | P13: Обсяг надходжень до бюджету ТГ від сплати єдиного податку СПД в ІТ-галузі за звітний рік (ОВ: грн) | Q13: Бал індикатора присвоюється пропорційно до розрахованого значення у відношенні до цільового з кроком 1 бал, де 100 - максимальний бал, коли розраховане значення дорівнює цільовому, 0 - мінімальний бал | R13: Формула розрахунку - [(Показник 1.1/Показник 1.2)*100%], де Показник 1.1 – обсяг надходжень до бюджету ТГ від сплати єдиного податку СПД ІТ-галузі за звітний рік, грн Показник 1.2 - Загальний обсяг надходжень до бюджету ТГ від сплати єдиного податку СПД за звітний рік, грн | T13: Обсяг надходжень від сплати єдиного податку СПД в ІТ-галузі – обсяг коштів, що надійшли до бюджету ТГ від сплати суб'єктами податку на доходи фізичних осіб суб'єктами підприємницької діяльності, основною діяльністю яких є такі КВЕД: 62.01 Комп’ютерне програмування; 62.02 Консультування з питань інформатизації; 62.09 Інша діяльність у сфері інформаційних технологій і комп'ютерних систем. 58.21 Видання комп'ютерних ігор; 58.29 Видання іншого програмного забезпечення; 63.11 Оброблення даних, розміщення інформації на веб-вузлах і пов’язана з ними діяльність; 18.20 Тиражування звуко-, відеозаписів і програмного забезпечення; 47.41 Роздрібна торгівля комп’ютерами, периферійним устаткуванням і програмним забезпеченням у спеціалізованих магазинах; Обсяг надходжень від сплати єдиного податку – обсяг коштів, що надійшли до бюджету ТГ від сплати суб'єктами єдиного податку за такими кодами класифікації доходів: 18050100 18050200 18050300 18050301 18050400 18050401 18050500 18050501 | U13: за рік | V13: Бюджетний кодекс України https://zakon.rada.gov.ua/laws/show/2456-17#Text Наказ Міністерства фінансів "Про бюджетну класифікацію" №11 від 14 січня 2011 https://zakon.rada.gov.ua/rada/show/v0011201-11#Text | W13: Дані Державної податкової служби
B14: Цифрова економіка в ТГ | C14: Розвиток підприємств ІТ-сектору в ТГ | D14: A.1.5 | E14: % у надходженнях від сплати єдиного податку в бюджет ТГ, що надійшли від CПД з КВЕД ІТ-галузі | G14: % | H14: Базовий | I14: Обов'язковий для вимірювання | J14: Кількісні дані | K14: 0.1 | L14: =VLOOKUP(D14,'Перелік Iндикаторiв'!$D$4:$M$99,8,FALSE) -> 0.1 | M14: =VLOOKUP(D14,'Перелік Iндикаторiв'!$D$4:$M$99,9,FALSE) -> 0.15384615 | O14: A.1.5.2 | P14: Загальний обсяг надходжень до бюджету ТГ від сплати єдиного податку СПД за звітний рік (ОВ: грн) | Q14: Бал індикатора присвоюється пропорційно до розрахованого значення у відношенні до цільового з кроком 1 бал, де 100 - максимальний бал, коли розраховане значення дорівнює цільовому, 0 - мінімальний бал | R14: Формула розрахунку - [(Показник 1.1/Показник 1.2)*100%], де Показник 1.1 – обсяг надходжень до бюджету ТГ від сплати єдиного податку СПД в ІТ-галузі за звітний рік, грн Показник 1.2 - Загальний обсяг надходжень до бюджету ТГ від сплати єдиного податку СПД за звітний рік, грн | T14: Обсяг надходжень від сплати єдиного податку – обсяг коштів, що надійшли до бюджету ТГ від сплати суб'єктами єдиного податку за такими кодами класифікації доходів: 18050100 18050200 18050300 18050301 18050400 18050401 18050500 18050502 | U14: за рік | V14: Бюджетний кодекс України https://zakon.rada.gov.ua/laws/show/2456-17#Text Наказ Міністерства фінансів "Про бюджетну класифікацію" №11 від 14 січня 2011 https://zakon.rada.gov.ua/rada/show/v0011201-11#Text | W14: Дані Державної податкової служби
B15: Цифрова економіка в ТГ | C15: Розвиток підприємств ІТ-сектору в ТГ | D15: A.1.6 | E15: % нових робочих місць, створених у підприємствах ІТ-галузі у загальній кількості нових робочих місць за звітній період | G15: % | H15: Базовий | I15: На майбутнє вимірювання | J15: Кількісні дані | K15: 0.15 | L15: =VLOOKUP(D15,'Перелік Iндикаторiв'!$D$4:$M$99,8,FALSE) -> 0.1 | M15: =VLOOKUP(D15,'Перелік Iндикаторiв'!$D$4:$M$99,9,FALSE) -> 0.14285714 | O15: A.1.6.1 | P15: Кількість створених нових робочих місць в ІТ-галузі у ТГ за звітний період (ОВ: робочих місць) | Q15: Бал індикатора присвоюється пропорційно до розрахованого значення у відношенні до цільового з кроком 1 бал, де 100 - максимальний бал, коли розраховане значення дорівнює цільовому, 0 - мінімальний бал | R15: Формула розрахунку - [((Показник 1.1/Показник 1.2)*100%], де Показник 1.1 - Кількість створених нових робочих місць в ІТ-галузі в ТГ за звітний період, робочих місць Показник 1.2 - Загальна кількість створених нових робочих місць у ТГ за звітний період, робочих місць | T15: Нове робоче місце на підприємствах в ІТ-галузі – утворення штатної кількості працівників у зв’язку зі створенням нового суб’єкта господарювання (окрім створеного шляхом припинення) або збільшенням штатної кількості працівників на підприємствах, основною діяльністю яких є такі КВЕД: 62.01 Комп’ютерне програмування; 62.02 Консультування з питань інформатизації; 62.09 Інша діяльність у сфері інформаційних технологій і комп'ютерних систем. 58.21 Видання комп'ютерних ігор; 58.29 Видання іншого програмного забезпечення; 63.11 Оброблення даних, розміщення інформації на веб-вузлах і пов’язана з ними діяльність; 18.20 Тиражування звуко-, відеозаписів і програмного забезпечення; 47.41 Роздрібна торгівля комп’ютерами, периферійним устаткуванням і програмним забезпеченням у спеціалізованих магазинах; | U15: за рік | V15: Закон України "Про зайнятість населення" https://zakon.rada.gov.ua/laws/show/5067-17#Text | W15: Дані Державної служби зайнятості
B16: Цифрова економіка в ТГ | C16: Розвиток підприємств ІТ-сектору в ТГ | D16: A.1.6 | E16: % нових робочих місць, створених на підприємствах ІТ-галузі від загальної кількості нових робочих місць за звітній період | G16: % | H16: Базовий | I16: На майбутнє вимірювання | J16: Кількісні дані | K16: 0.15 | L16: =VLOOKUP(D16,'Перелік Iндикаторiв'!$D$4:$M$99,8,FALSE) -> 0.1 | M16: =VLOOKUP(D16,'Перелік Iндикаторiв'!$D$4:$M$99,9,FALSE) -> 0.14285714 | O16: A.1.6.2 | P16: Загальна кількість створених нових робочих місць у ТГ за звітний період (ОВ: робочих місць) | Q16: Бал індикатора присвоюється пропорційно до розрахованого значення у відношенні до цільового з кроком 1 бал, де 100 - максимальний бал, коли розраховане значення дорівнює цільовому, 0 - мінімальний бал | R16: Формула розрахунку - [((Показник 1.1/Показник 1.2)*100%], де Показник 1.1 - Кількість створених нових робочих місць в ІТ-галузі в ТГ за звітний період, робочих місць Показник 1.2 - Загальна кількість створених нових робочих місць у ТГ за звітний період, робочих місць | T16: Нове робоче місце – утворення штатної кількості працівників у зв’язку зі створенням нового суб’єкта господарювання (окрім створеного шляхом припинення) або збільшенням штатної кількості працівників за умови, що за попередні 12 місяців середньомісячна чисельність не скорочувалася (не зменшувалася). Новим робоче місце вважається й тоді, коли воно створене шляхом модернізації або зміни технології виробництва, що потребує нових знань та вмінь працівника. | U16: за рік | V16: Закон України "Про зайнятість населення" https://zakon.rada.gov.ua/laws/show/5067-17#Text | W16: Дані Державної служби зайнятості
B17: Цифрова економіка в ТГ | C17: Розвиток підприємств ІТ-сектору в ТГ | D17: A.1.7 | E17: Відношення середньої заробітної плати в ІТ-галузі у ТГ до середньої заробітної плати в ТГ | F17: Відношення середньої заробітної плати в ІТ-галузі у ТГ до середньої заробітної плати в ТГ | G17: % | H17: Базовий | I17: Обов'язковий для вимірювання | J17: Кількісні дані | K17: 1.5 | L17: =VLOOKUP(D17,'Перелік Iндикаторiв'!$D$4:$M$99,8,FALSE) -> 1.5 | M17: =VLOOKUP(D17,'Перелік Iндикаторiв'!$D$4:$M$99,9,FALSE) -> 0.13186813 | O17: A.1.7.1 | P17: Середньомісячна заробітна плата найманих працівників на підприємствах, які провадять діяльність в ІТ-галузі на території ТГ, у звітному році (ОВ: грн) | Q17: Бал індикатора присвоюється пропорційно до розрахованого значення у відношенні до цільового з кроком 1 бал, де 100 - максимальний бал, коли розраховане значення дорівнює цільовому, 0 - мінімальний бал | R17: Формула розрахунку - [(Показник 1.1/Показник 1.2)*100%] де, Показник 1.1 - Середньомісячна заробітна плата найманих працівників на підприємствах, які провадять діяльність в ІТ-галузі на території ТГ, у звітному році, грн Показник 1.2 - Середньомісячна заробітна плата найманих працівників на підприємствах та в організаціях, які провадять діяльність на території ТГ, у звітному році, грн | T17: Середньомісячна (номінальна) заробітна плата працівників ІТ-галузі – обсяг коштів, визначений шляхом ділення нарахованого фонду оплати праці за відповідний період на середньооблікову кількість працівників та на кількість місяців у звітному році, на підприємствах, основною діяльністю яких є такі КВЕД: 62.01 Комп’ютерне програмування; 62.02 Консультування з питань інформатизації; 62.09 Інша діяльність у сфері інформаційних технологій і комп'ютерних систем. 58.21 Видання комп'ютерних ігор; 58.29 Видання іншого програмного забезпечення; 63.11 Оброблення даних, розміщення інформації на веб-вузлах і пов’язана з ними діяльність; 18.20 Тиражування звуко-, відеозаписів і програмного забезпечення; 47.41 Роздрібна торгівля комп’ютерами, периферійним устаткуванням і програмним забезпеченням у спеціалізованих магазинах. | U17: за рік | V17: Наказ Державного комітету статистики України "Про затвердження Інструкції зі статистики заробітної плати" №5 від 13 січня 2004 https://zakon.rada.gov.ua/laws/show/z0114-04#Text | W17: Дані Державної податкової служби
B18: Цифрова економіка в ТГ | C18: Розвиток підприємств ІТ-сектору в ТГ | D18: A.1.7 | E18: Відношення середньої заробітної плати в ІТ-галузі у ТГ до середньої заробітної плати в ТГ | G18: % | H18: Базовий | I18: Обов'язковий для вимірювання | J18: Кількісні дані | K18: 1.5 | L18: =VLOOKUP(D18,'Перелік Iндикаторiв'!$D$4:$M$99,8,FALSE) -> 1.5 | M18: =VLOOKUP(D18,'Перелік Iндикаторiв'!$D$4:$M$99,9,FALSE) -> 0.13186813 | O18: A.1.7.2 | P18: Середньомісячна заробітна плата найманих працівників на підприємствах і в організаціях, які провадять діяльність на території ТГ, у звітному році (ОВ: грн) | Q18: Бал індикатора присвоюється пропорційно до розрахованого значення у відношенні до цільового з кроком 1 бал, де 100 - максимальний бал, коли розраховане значення дорівнює цільовому, 0 - мінімальний бал | R18: Формула розрахунку - [(Показник 1.1/Показник 1.2)*100%] де, Показник 1.1 - Середньомісячна заробітна плата найманих працівників на підприємствах, які провадять діяльність в ІТ-галузі на території ТГ, у звітному році, грн Показник 1.2 - Середньомісячна заробітна плата найманих працівників на підприємствах та в організаціях, які провадять діяльність на території ТГ, у звітному році, грн | T18: Середньомісячна (номінальна) заробітна плата працівників на підприємствах, зареєстрованими в ТГ – обсяг коштів, визначений шляхом ділення нарахованого фонду оплати праці за відповідний період на середньооблікову кількість працівників та на кількість місяців у звітному році. | U18: за рік | V18: Наказ Державного комітету статистики України "Про затвердження Інструкції зі статистики заробітної плати" №5 від 13 січня 2004 https://zakon.rada.gov.ua/laws/show/z0114-04#Text | W18: Дані Державної податкової служби
B19: Цифрова економіка в ТГ | C19: Розвиток підприємств ІТ-сектору в ТГ | D19: A.1.8 | E19: Відношення середньої заробітної плати в ІТ-галузі у ТГ до середньої заробітної плати в ІТ-галузі в Україні | G19: % | H19: Базовий | I19: На майбутнє вимірювання | J19: Кількісні дані | K19: 1.2 | L19: =VLOOKUP(D19,'Перелік Iндикаторiв'!$D$4:$M$99,8,FALSE) -> 1.2 | M19: =VLOOKUP(D19,'Перелік Iндикаторiв'!$D$4:$M$99,9,FALSE) -> 0.13186813 | O19: A.1.8.1 | P19: Середньомісячна заробітна плата найманих працівників на підприємствах, які провадять діяльність в ІТ-галузі на території ТГ (ОВ: грн) | Q19: Бал індикатора присвоюється пропорційно до розрахованого значення у відношенні до цільового з кроком 1 бал, де 100 - максимальний бал, коли розраховане значення дорівнює цільовому, 0 - мінімальний бал | R19: Формула розрахунку - [(Показник 1.1/Показник 1.2)*100%] де, Показник 1.1 - Середньомісячна заробітна плата найманих працівників на підприємствах, які провадять діяльність в ІТ-галузі на території ТГ, грн Показник 1.2 - Середньомісячна заробітна плата найманих працівників на підприємствах, які провадять діяльність в ІТ-галузі на території України, грн | T19: Середньомісячна (номінальна) заробітна плата працівників ІТ-галузі у ТГ – обсяг коштів, визначений шляхом ділення нарахованого фонду оплати праці за відповідний період на середньооблікову кількість працівників та на кількість місяців у звітному році, на підприємствах, основною діяльністю яких є такі КВЕД: 62.01 Комп’ютерне програмування; 62.02 Консультування з питань інформатизації; 62.09 Інша діяльність у сфері інформаційних технологій і комп'ютерних систем. 58.21 Видання комп'ютерних ігор; 58.29 Видання іншого програмного забезпечення; 63.11 Оброблення даних, розміщення інформації на веб-вузлах і пов’язана з ними діяльність; 18.20 Тиражування звуко-, відеозаписів і програмного забезпечення; 47.41 Роздрібна торгівля комп’ютерами, периферійним устаткуванням і програмним забезпеченням у спеціалізованих магазинах; | U19: за рік | V19: Наказ Державного комітету статистики України "Про затвердження Інструкції зі статистики заробітної плати" №5 від 13 січня 2004 https://zakon.rada.gov.ua/laws/show/z0114-04#Text | W19: Дані Державної податкової служби
B20: Цифрова економіка в ТГ | C20: Розвиток підприємств ІТ-сектору в ТГ | D20: A.1.8 | E20: Відношення середньої заробітної плати в ІТ-галузі у ТГ до середньої заробітної плати в ІТ-галузі в Україні | G20: % | H20: Базовий | I20: На майбутнє вимірювання | J20: Кількісні дані | K20: 1.2 | L20: =VLOOKUP(D20,'Перелік Iндикаторiв'!$D$4:$M$99,8,FALSE) -> 1.2 | M20: =VLOOKUP(D20,'Перелік Iндикаторiв'!$D$4:$M$99,9,FALSE) -> 0.13186813 | O20: A.1.8.2 | P20: Середньомісячна заробітна плата найманих працівників на підприємствах, які провадять діяльність в ІТ-галузі на території України (ОВ: грн) | Q20: Бал індикатора присвоюється пропорційно до розрахованого значення у відношенні до цільового з кроком 1 бал, де 100 - максимальний бал, коли розраховане значення дорівнює цільовому, 0 - мінімальний бал | R20: Формула розрахунку - [(Показник 1.1/Показник 1.2)*100%] де, Показник 1.1 - Середньомісячна заробітна плата найманих працівників на підприємствах, які провадять діяльність в ІТ-галузі на території ТГ, грн Показник 1.2 - Середньомісячна заробітна плата найманих працівників на підприємствах, які провадять діяльність в ІТ-галузі на території України, грн | T20: Середньомісячна (номінальна) заробітна плата працівників ІТ-галузі в Україні – обсяг коштів, визначений шляхом ділення нарахованого фонду оплати праці за відповідний період на середньооблікову кількість працівників та на кількість місяців у звітному році, на підприємствах в Україні, основною діяльністю яких є такі КВЕД: 62.01 Комп’ютерне програмування; 62.02 Консультування з питань інформатизації; 62.09 Інша діяльність у сфері інформаційних технологій і комп'ютерних систем. 58.21 Видання комп'ютерних ігор; 58.29 Видання іншого програмного забезпечення; 63.11 Оброблення даних, розміщення інформації на веб-вузлах і пов’язана з ними діяльність; 18.20 Тиражування звуко-, відеозаписів і програмного забезпечення; 47.41 Роздрібна торгівля комп’ютерами, периферійним устаткуванням і програмним забезпеченням у спеціалізованих магазинах; | U20: за рік | V20: Наказ Державного комітету статистики України "Про затвердження Інструкції зі статистики заробітної плати" №5 від 13 січня 2004 https://zakon.rada.gov.ua/laws/show/z0114-04#Text | W20: Дані Державної податкової служби
B21: Цифрова економіка в ТГ | C21: Розвиток підприємств ІТ-сектору в ТГ | D21: A.1.9 | E21: Частка жінок на керівних посадах у підприємствах ІТ-галузі в ТГ | G21: % | I21: На майбутнє вимірювання | J21: Кількісні дані | K21: 0.5 | L21: =VLOOKUP(D21,'Перелік Iндикаторiв'!$D$4:$M$99,8,FALSE) -> 0,5 | M21: =VLOOKUP(D21,'Перелік Iндикаторiв'!$D$4:$M$99,9,FALSE) -> 0 | O21: A.1.9.1 | P21: Працівники жіночої статі, зазначеніi в реєстрi ЄДРПОУ як керівники підприємств в ІТ-галузі (ОВ: осіб) | Q21: Бал індикатора присвоюється пропорційно до розрахованого значення у відношенні до цільового з кроком 1 бал, де 100 - максимальний бал, коли розраховане значення дорівнює цільовому, 0 - мінімальний бал | R21: Формула розрахунку - [(Показник 1.1/Показник 1.2)*100%] де, Показник 1.1 - Працівники жіночої статі, зазначеніi в реєстрi ЄДРПОУ як керівники підприємств у ІТ-галузі, осіб Показник 1.2 - Працівники чоловічої статі, зазначеніi в реєстрi ЄДРПОУ як керівники підприємств у ІТ-галузі, осіб | T21: Працівники жіночої статі, зазначеніi в реєстрi ЄДРПОУ як керівники підприємств в ІТ-галузі – наймані працівниці, займані посади яких пов'язані зі здійсненням різноманітних функцій управління та керівництва та відповідають розділу 1 Класифікатора професій ДК 003:2010 на підприємствах, зареєстрованих на території ТГ, основною діяльністю яких є такі КВЕД: 62.01 Комп’ютерне програмування; 62.02 Консультування з питань інформатизації; 62.09 Інша діяльність у сфері інформаційних технологій і комп'ютерних систем. 58.21 Видання комп'ютерних ігор; 58.29 Видання іншого програмного забезпечення; 63.11 Оброблення даних, розміщення інформації на веб-вузлах і пов’язана з ними діяльність; 18.20 Тиражування звуко-, відеозаписів і програмного забезпечення; 47.41 Роздрібна торгівля комп’ютерами, периферійним устаткуванням і програмним забезпеченням у спеціалізованих магазинах. | U21: станом на 01.01.2022 | V21: Наказ Державного Комітету УКРАЇНИ З ПИТАНЬ ТЕХНІЧНОГО РЕГУЛЮВАННЯ ТА СПОЖИВЧОЇ ПОЛІТИКИ № 327 від 28.07.2010 Про затвердження, внесення зміни та скасування нормативних документів https://zakon.rada.gov.ua/rada/show/v0327609-10#Text | W21: Дані Державної податкової служби
B22: Цифрова економіка в ТГ | C22: Розвиток підприємств ІТ-сектору в ТГ | D22: A.1.9 | E22: Частка жінок на керівних посадах у підприємствах ІТ-галузі в ТГ | G22: % | I22: На майбутнє вимірювання | J22: Кількісні дані | K22: 0.5 | L22: =VLOOKUP(D22,'Перелік Iндикаторiв'!$D$4:$M$99,8,FALSE) -> 0,5 | M22: =VLOOKUP(D22,'Перелік Iндикаторiв'!$D$4:$M$99,9,FALSE) -> 0 | O22: A.1.9.2 | P22: Працівники чоловічої статі, зазначеніi в реєстрi ЄДРПОУ як керівники підприємств в ІТ-галузі (ОВ: осіб) | Q22: Бал індикатора присвоюється пропорційно до розрахованого значення у відношенні до цільового з кроком 1 бал, де 100 - максимальний бал, коли розраховане значення дорівнює цільовому, 0 - мінімальний бал | R22: Формула розрахунку - [(Показник 1.1/Показник 1.2)*100%] де, Показник 1.1 - Працівники жіночої статі, зазначеніi в реєстрi ЄДРПОУ як керівники підприємств в ІТ-галузі, осіб Показник 1.2 - Працівники чоловічої статі, зазначеніi в реєстрi ЄДРПОУ як керівники підприємств в ІТ-галузі, осіб | T22: Працівники чоловічої статі, зазначеніi в реєстрi ЄДРПОУ як керівники підприємств в ІТ-галузі – наймані працівники, займані посади яких пов'язані із здійсненням різноманітних функцій управління та керівництва та відповідають розділу 1 Класифікатора професій ДК 003:2010 на підприємствах, зареєстрованих на території ТГ, основною діяльністю яких є такі КВЕД: 62.01 Комп’ютерне програмування; 62.02 Консультування з питань інформатизації; 62.09 Інша діяльність у сфері інформаційних технологій і комп'ютерних систем. 58.21 Видання комп'ютерних ігор; 58.29 Видання іншого програмного забезпечення; 63.11 Оброблення даних, розміщення інформації на веб-вузлах і пов’язана з ними діяльність; 18.20 Тиражування звуко-, відеозаписів і програмного забезпечення; 47.41 Роздрібна торгівля комп’ютерами, периферійним устаткуванням і програмним забезпеченням у спеціалізованих магазинах; | U22: станом на 01.01.2022 | V22: Наказ Державного Комітету УКРАЇНИ З ПИТАНЬ ТЕХНІЧНОГО РЕГУЛЮВАННЯ ТА СПОЖИВЧОЇ ПОЛІТИКИ № 327 від 28.07.2010 Про затвердження, внесення зміни та скасування нормативних документів https://zakon.rada.gov.ua/rada/show/v0327609-10#Text | W22: Дані Державної податкової служби
B23: Цифрова економіка в ТГ | C23: Розвиток підприємств ІТ-сектору в ТГ | D23: A.1.10 | E23: Частка локальних ІТ підприємств, залучених до програми Дія Сіті, в загальній кількості ІТ-підприємств | G23: % | H23: Базовий | I23: На майбутнє вимірювання | J23: Кількісні дані | K23: 0.005 | L23: =VLOOKUP(D23,'Перелік Iндикаторiв'!$D$4:$M$99,8,FALSE) -> 0.005 | M23: =VLOOKUP(D23,'Перелік Iндикаторiв'!$D$4:$M$99,9,FALSE) -> 0.13186813 | O23: A.1.10.1 | P23: Кількість СПД в ІТ-галузі, залучених до програми Дія Сіті, які є резидентами Дія Сіті (ОВ: резидентів) | Q23: Бал індикатора присвоюється пропорційно до розрахованого значення у відношенні до цільового з кроком 1 бал, де 100 - максимальний бал, коли розраховане значення дорівнює цільовому, 0 - мінімальний бал | R23: Формула розрахунку - [(Показник 1.1/Показник 1.2)*100%] де, Показник 1.1 - Кількість СПД в ІТ-галузі, залучених до програми Дія Сіті, які є резидентами Дія Сіті, СПД Показник 1.2 - Загальна кількість СПД в ІТ-галузі на території ТГ, СПД | T23: Резидент Дія Сіті – юридична особа, яка відповідно до цього Закону набула статусу резидента Дія Сіті та згідно з інформацією, що міститься у реєстрі Дія Сіті, перебуває у зазначеному статусі. | U23: станом на 01.01.2022 | V23: Закон України «Про стимулювання розвитку цифрової економіки в Україні» https://zakon.rada.gov.ua/laws/show/1667-20#Text Закон України «Про внесення змін до Податкового кодексу України щодо стимулювання розвитку цифрової економіки в Україні» https://zakon.rada.gov.ua/laws/show/1946-20#Text | W23: Дані підрозділу Міністерства цифрової трансформації
